Workbook
Name _1星: Sheet1!$E$2:$E$6
Name _2星: Sheet1!$D$2:$D$6
Name _3星: Sheet1!$C$2:$C$10
Name _4星: Sheet1!$B$2:$B$10
Name _5星: Sheet1!$A$2:$A$10
Name 组织管理评价: Sheet1!$A$2:$A$10

Sheet 2015年上半年目标制定表
B1: XXX(部门) 2015H1二级BSC目标制定表
B2: Part1：业务评价（建议聚焦5-8项重点产品或核心领域）
B3: 核心领域/产品/项目 | C3: 关键策略 | D3: 衡量标准 | E3: 权重 | F3: 责任主体 | G3: 自评 | I3: 上级评估（部门第一负责人的上级） | K3: SEVP评估 | Q3: 上级评估赋值 | R3: SEVP评估赋值
G4: 等级 | H4: 说明 | I4: 等级 | J4: 说明 | K4: 等级 | L4: 说明
B5: ，可按聚焦的重点产品/项目或者领域填写 | C5: 按产品维度聚焦描述具体的几条关键策略，要求：简单、清晰、到位 | D5: 从“用户价值、效能价值”等纬度定性/定量描述 | E5: 一个产品/领域对应一个权重 | F5: 每个产品/领域/项目的首要责任人 | G5: 5大档 | H5: 按产品维度拉通，重点描述战略目标达成情况，并说明目标达成外的价值贡献（按产品维度填写，字数建议控制在200字内），建议可以从”用户价值、商业价值、效能价值“几个维度展开，通过与历史比、与行业比来综合评判
B6: 运维服务能力提升 | C6: 完善蓝鲸PaaS平台能力，推进游戏基础运维工作的自助/自动化。 | D6: 1、基础运维能力提升：四星级以上业务及新业务的发布变更、开区迁移、扩容缩容等基础运维场景的自助服务比例提升至50%，通过智能监控和故障自愈项目构建故障的发现分析处理的自动化，实现100款业务的50%故障处理无人值守。 2、提高平台的安全性和稳定性：通过docker等新技术增强PaaS平台上APP间的隔离安全性，不出现用户间信息泄露事件，通过对ESB平台的高可用改造提升平台整体可用性高至99.9%以上。 | E6: 0.2 | P6: =IFERROR(VLOOKUP(G6,Sheet22!A:B,2,0),0) -> 0 | Q6: =IFERROR(VLOOKUP(I6,Sheet22!A:B,2,0),0) -> 0 | R6: =IFERROR(VLOOKUP(K6,Sheet22!A:B,2,0),0) -> 0 | S6: 4星+
C7: 强化数据分析和智能决策能力，完善运维闭环服务支撑系统，提高运维闭环服务的覆盖面； | D7: 1、登录体验优化服务: 登录异常跟踪覆盖60%接入TCLS端游业务，优化后6星业务的登录投诉平均下降30%； 2、下载体验优化服务： 下载优化服务覆盖60%接入TCLS的端游业务，100m以内的更新包的下载更新时间控制在3分钟之内； 3、版本发布服务： 覆盖50%接入标准化发布的业务，版本健康度分数大于90分； 4、智能扩缩容服务（智能扩缩容服务可以做到自动判断是否需要扩缩容，并在人工确认之后自动完成扩缩容操作，可以大大提高扩缩容的效率，降低产品和运维的工作量）： 扩缩容服务接入60%有需求的端游业务的数据，其中40%的业务实现智能扩缩容，智能扩缩容准确率达到80%； | E7: 0.2 | P7: =IFERROR(VLOOKUP(G7,Sheet22!A:B,2,0),0) -> 0 | Q7: =IFERROR(VLOOKUP(I7,Sheet22!A:B,2,0),0) -> 0 | R7: =IFERROR(VLOOKUP(K7,Sheet22!A:B,2,0),0) -> 0 | S7: 4星
B8: 数据化营销 | C8: iData数据服务： 为业务提供一站式的腾讯游戏数据服务，以游戏生命周期打造数据化运营闭环。 | D8: 1、数据到营销功能打通： 通过看数据直接发起信鸽、CTIPS的营销支持； 自助投放信鸽、CTIPS渠道覆盖率90%; 2、运营分析功能丰富： 实现用户类指标快捷提取、下钻、跟踪、画像分析功能打通 提取+下钻+跟踪后台周均任务数 10000; 3、内容场景化建设： 完成”新进用户”专题、”活跃用户”专题 月专题页面访问周均次数1000 ; 4、业务接入 完成5星(含准5星)业务场景化专题接入 完成5星(含准5星)业务下钻和用户画像分析接入 完成5星(含准5星)业务CTIPS（端游）、信鸽（手游）在iData接入 | P8: =IFERROR(VLOOKUP(G8,Sheet22!A:B,2,0),0) -> 0 | Q8: =IFERROR(VLOOKUP(I8,Sheet22!A:B,2,0),0) -> 0 | R8: =IFERROR(VLOOKUP(K8,Sheet22!A:B,2,0),0) -> 0 | S8: 4星-
C9: 道聚城： 提供基础道具管理平台、灵活多样的促销活动形式，以及游戏差异化的运营服务内容，最终帮助业务提升收入 | D9: 2015上半年重点，通过自助化、开放化建设，以及监控加固，提升平台服务能力，达到业务可快速接入上线及稳定运营； 1、自助： a) 业务接入自助：接入全流程化；开发外包化（不包含验收投入）；可达到新接入8款业务（3款端游、5款手游） b) 业务运营自助：固化3种促销活动模版，实现产品自助 2、开放： 服务能力开放：实现合作项目购买环节，道具接口、订单支付组件的开放；在2+个项目上试点 3、监控： a) 完成订单（包括支付金额、方式）的准实时监控 b) 完成道具发送数量、频率、价值数据的准实时监控 c) 实现购物点、优惠券的对账
C10: 数据挖掘： 为游戏精细化运营提供数据挖掘服务能力并落地应用 | D10: 【业务能力】 1、道具推荐： 业务量： 完成对LOL、逆战、炫舞、飞车的覆盖 新场景拓展：在LOL等游戏进行游戏内的精细化场景推荐，协助LOL在新场景上完成8亿收入。 游戏原有场景优化：在原有售卖渠道上通过推荐带来5%以上的收益提升 2、广告推荐： 业务量：完成QQ游戏大厅广告、市场部O2广告的推荐工作 3、精准营销（精准拉新/拉回流/拉付费）： 业务量：覆盖天天酷跑、天天炫斗、MT2等全部精品手游，以及CF、LOL、DNF、CODOL等所有五/六星级PC端业务 【平台能力】 1、服务能力： 推荐引擎能够支撑日PV 50亿以上流量 2、用户画像： 覆盖天天酷跑、天天炫斗、MT2等全部精品手游，以及CF、LOL、DNF、CODOL等所有五/六星级PC端业务
B11: 心悦差异化特权服务 | C11: 通过深化渠道运营，增强高端用户触达能力；同时进一步打造基于数据分析的精细化运营能力，使用户生命周期在心悦特权关怀下更趋健康。 | D11: 完成对短信、官网、微官网、Ingame等渠道的梳理和优化，对利用低、体验差、缺失的内容及模块进行优化完善和扩充，提升心悦与用户接触能力，并细化接触的场景与体验，通过精准识别、渠道数据监控，完善内容与路径。最终使心悦特权活跃率持续提升至45%。 | P11: =IFERROR(VLOOKUP(G11,Sheet22!A:B,2,0),0) -> 0 | Q11: =IFERROR(VLOOKUP(I11,Sheet22!A:B,2,0),0) -> 0 | R11: =IFERROR(VLOOKUP(K11,Sheet22!A:B,2,0),0) -> 0 | S11: 3星+
P12: =IFERROR(VLOOKUP(G12,Sheet22!A:B,2,0),0) -> 0 | Q12: =IFERROR(VLOOKUP(I12,Sheet22!A:B,2,0),0) -> 0 | R12: =IFERROR(VLOOKUP(K12,Sheet22!A:B,2,0),0) -> 0 | S12: 3星
P13: =IFERROR(VLOOKUP(G13,Sheet22!A:B,2,0),0) -> 0 | Q13: =IFERROR(VLOOKUP(I13,Sheet22!A:B,2,0),0) -> 0 | R13: =IFERROR(VLOOKUP(K13,Sheet22!A:B,2,0),0) -> 0 | S13: 3星-
P14: =IFERROR(VLOOKUP(G14,Sheet22!A:B,2,0),0) -> 0 | Q14: =IFERROR(VLOOKUP(I14,Sheet22!A:B,2,0),0) -> 0 | R14: =IFERROR(VLOOKUP(K14,Sheet22!A:B,2,0),0) -> 0 | S14: 2星
P15: =IFERROR(VLOOKUP(G15,Sheet22!A:B,2,0),0) -> 0 | Q15: =IFERROR(VLOOKUP(I15,Sheet22!A:B,2,0),0) -> 0 | R15: =IFERROR(VLOOKUP(K15,Sheet22!A:B,2,0),0) -> 0 | S15: 1星
P16: =IFERROR(VLOOKUP(G16,Sheet22!A:B,2,0),0) -> 0 | Q16: =IFERROR(VLOOKUP(I16,Sheet22!A:B,2,0),0) -> 0 | R16: =IFERROR(VLOOKUP(K16,Sheet22!A:B,2,0),0) -> 0
P17: =IFERROR(VLOOKUP(G17,Sheet22!A:B,2,0),0) -> 0 | Q17: =IFERROR(VLOOKUP(I17,Sheet22!A:B,2,0),0) -> 0 | R17: =IFERROR(VLOOKUP(K17,Sheet22!A:B,2,0),0) -> 0
P18: =IFERROR(VLOOKUP(G18,Sheet22!A:B,2,0),0) -> 0 | Q18: =IFERROR(VLOOKUP(I18,Sheet22!A:B,2,0),0) -> 0 | R18: =IFERROR(VLOOKUP(K18,Sheet22!A:B,2,0),0) -> 0
P19: =IFERROR(VLOOKUP(G19,Sheet22!A:B,2,0),0) -> 0 | Q19: =IFERROR(VLOOKUP(I19,Sheet22!A:B,2,0),0) -> 0 | R19: =IFERROR(VLOOKUP(K19,Sheet22!A:B,2,0),0) -> 0
P20: =IFERROR(VLOOKUP(G20,Sheet22!A:B,2,0),0) -> 0 | Q20: =IFERROR(VLOOKUP(I20,Sheet22!A:B,2,0),0) -> 0 | R20: =IFERROR(VLOOKUP(K20,Sheet22!A:B,2,0),0) -> 0
P21: =IFERROR(VLOOKUP(G21,Sheet22!A:B,2,0),0) -> 0 | Q21: =IFERROR(VLOOKUP(I21,Sheet22!A:B,2,0),0) -> 0 | R21: =IFERROR(VLOOKUP(K21,Sheet22!A:B,2,0),0) -> 0
B22: 合计 | E22: =IF(SUM(E6:E18)<100%,100%,SUM(E6:E18)) -> 1 | F22: 系统测算等级 | G22: =IF(P22=0,"——",HLOOKUP(Sheet22!$A$1,Sheet22!$A$2:$A$10,MATCH(P22,Sheet22!$B$2:$B$10,-1))) -> —— | I22: =IF(Q22=0,"——",HLOOKUP(Sheet22!$A$1,Sheet22!$A$2:$A$10,MATCH(Q22,Sheet22!$B$2:$B$10,-1))) -> —— | K22: =IF(R22=0,"——",HLOOKUP(Sheet22!$A$1,Sheet22!$A$2:$A$10,MATCH(R22,Sheet22!$B$2:$B$10,-1))) -> —— | P22: =SUMPRODUCT(E6:E21,P6:P21) -> 0 | Q22: =SUMPRODUCT(E6:E21,Q6:Q21) -> 0 | R22: =SUMPRODUCT(E6:E21,R6:R21) -> 0
F23: 最终等级 | P23: SUMPRODUCT(H6:H22,AB6:AB22)
B25: Part2：组织管理评价
B26: 牵引方向 | C26: 衡量标准 | E26: 参考指标 | G26: 权重 | H26: 自评 | J26: 上级评估 | L26: SEVP评估
H27: 等级 | I27: 说明 | J27: 等级 | K27: 说明 | L27: 等级 | M27: 说明
B28: 组织活力提升 | C28: 用于牵引BG/部门关注资源的盘活和聚焦，确保资源向重点项目倾斜（尤其是HC资源），同时关注每位员工是否有清晰的目标感（尤其是重点项目基干的目标是否清晰）和成就感，激发他们的动力，确保重点项目业绩达成 | E28: 人均产出比，组织及汇报关系合理性，敬业度数据，员工目标制定达成率及质量，重点资源配置情况等。 | G28: 1
B29: 关键能力提升 | C29: 用于牵引BG/部门关注“一线经理管理能力、核心人才领导力、产品经理能力、移动互联网能力”的培养和提升，加速领军人才培养和战略关键人才挖掘 | E29: 关键人才梯队建设情况，专业职级晋升率，领导力360评估
B30: 骨干流失情况 | C30: 用于鼓励部门关注组织氛围建设，减少员工主动流失率，尤其是骨干人员的流失。（骨干人员包括Teamleader及以上管理干部和专业三级及以上员工） | E30: 关键人才流失率
B31: 合计 | G31: 最终等级
B33: Part3：综合评价
B34: 评价结果 | C34: 自评 | D34: 上级评估 | E34: SEVP评估 | G34: 评估要求
B35: Part1：业务评价 | C35: =IF(G23=0,"",G23) | D35: =IF(I23=0,"",I23) | E35: =IF(K23=0,"",K23) | G35: 组织管理作为综合评价门槛要求： 1、组织管理<=2星，综合评价最高为3星+； 2、其他情况，以业务评价为主，按实际评估。
B36: Part2：组织管理评价 | C36: =IF(H31=0,"",H31) | D36: =IF(J28=0,"",J28) | E36: =IF(L28=0,"",L28)
B37: Part3：综合评价
B40: 附录：评估标准说明如下：
B41: 评估等级 | C41: 参考分数段 | D41: 参考对应等级赋值
B42: 5星 | C42: 95~100 | D42: 100
B43: 4星+ | C43: 85~95 | D43: 95
B44: 4星 | D44: 90
...

Sheet Sheet1
A1: 5星 | B1: 4星 | C1: 3星 | D1: 2星 | E1: 1星
A2: 5星 | B2: 5星 | C2: 5星 | D2: 3星+ | E2: 3星+
A3: 4星+ | B3: 4星+ | C3: 4星+ | D3: 3星 | E3: 3星
A4: 4星 | B4: 4星 | C4: 4星 | D4: 3星- | E4: 3星-
A5: 4星- | B5: 4星- | C5: 4星- | D5: 2星 | E5: 2星
A6: 3星+ | B6: 3星+ | C6: 3星+ | D6: 1星 | E6: 1星
A7: 3星 | B7: 3星 | C7: 3星
A8: 3星- | B8: 3星- | C8: 3星-
A9: 2星 | B9: 2星 | C9: 2星
A10: 1星 | B10: 1星 | C10: 1星

Sheet Sheet11
A1: 5星 | B1: 4星 | C1: 3星 | D1: 2星 | E1: 1星
A2: 5星 | B2: 5星 | C2: 5星 | D2: 3星+ | E2: 3星+
A3: 4星+ | B3: 4星+ | C3: 4星+ | D3: 3星 | E3: 3星
A4: 4星 | B4: 4星 | C4: 4星 | D4: 3星- | E4: 3星-
A5: 4星- | B5: 4星- | C5: 4星- | D5: 2星 | E5: 2星
A6: 3星+ | B6: 3星+ | C6: 3星+ | D6: 1星 | E6: 1星
A7: 3星 | B7: 3星 | C7: 3星
A8: 3星- | B8: 3星- | C8: 3星-
A9: 2星 | B9: 2星 | C9: 2星
A10: 1星 | B10: 1星 | C10: 1星

Sheet Sheet22
A1: 评估等级 | B1: 赋值
A2: 5星 | B2: 100
A3: 4星+ | B3: 95
A4: 4星 | B4: 90
A5: 4星- | B5: 85
A6: 3星+ | B6: 83
A7: 3星 | B7: 82
A8: 3星- | B8: 80
A9: 2星 | B9: 75
A10: 1星 | B10: 70
